2017-10-16 17:12:28
[Failure instance: Traceback: <class '_mysql_exceptions.ProgrammingError'>: (1146, "Table 'spider.zhilian_position' doesn't exist")
/usr/local/Cellar/python3/3.6.1/Frameworks/Python.framework/Versions/3.6/lib/python3.6/threading.py:916:_bootstrap_inner
/usr/local/Cellar/python3/3.6.1/Frameworks/Python.framework/Versions/3.6/lib/python3.6/threading.py:864:run
/Users/monstar/Envs/Spider/lib/python3.6/site-packages/twisted/_threads/_threadworker.py:46:work
/Users/monstar/Envs/Spider/lib/python3.6/site-packages/twisted/_threads/_team.py:190:doWork
--- <exception caught here> ---
/Users/monstar/Envs/Spider/lib/python3.6/site-packages/twisted/python/threadpool.py:250:inContext
/Users/monstar/Envs/Spider/lib/python3.6/site-packages/twisted/python/threadpool.py:266:<lambda>
/Users/monstar/Envs/Spider/lib/python3.6/site-packages/twisted/python/context.py:122:callWithContext
/Users/monstar/Envs/Spider/lib/python3.6/site-packages/twisted/python/context.py:85:callWithContext
/Users/monstar/Envs/Spider/lib/python3.6/site-packages/twisted/enterprise/adbapi.py:477:_runInteraction
/Users/monstar/Envs/Spider/lib/python3.6/site-packages/twisted/python/compat.py:477:reraise
/Users/monstar/Envs/Spider/lib/python3.6/site-packages/twisted/enterprise/adbapi.py:467:_runInteraction
/Users/monstar/Desktop/ProjectCode/bigdatarecruit/SpiderMan/RecruitSpider/RecruitSpider/pipelines.py:109:do_insert_position
/Users/monstar/Envs/Spider/lib/python3.6/site-packages/MySQLdb/cursors.py:250:execute
/Users/monstar/Envs/Spider/lib/python3.6/site-packages/MySQLdb/connections.py:50:defaulterrorhandler
/Users/monstar/Envs/Spider/lib/python3.6/site-packages/MySQLdb/cursors.py:247:execute
/Users/monstar/Envs/Spider/lib/python3.6/site-packages/MySQLdb/cursors.py:411:_query
/Users/monstar/Envs/Spider/lib/python3.6/site-packages/MySQLdb/cursors.py:374:_do_query
/Users/monstar/Envs/Spider/lib/python3.6/site-packages/MySQLdb/connections.py:292:query
]2017-10-16 17:12:28
[Failure instance: Traceback: <class '_mysql_exceptions.ProgrammingError'>: (1146, "Table 'spider.zhilian_company' doesn't exist")
/usr/local/Cellar/python3/3.6.1/Frameworks/Python.framework/Versions/3.6/lib/python3.6/threading.py:916:_bootstrap_inner
/usr/local/Cellar/python3/3.6.1/Frameworks/Python.framework/Versions/3.6/lib/python3.6/threading.py:864:run
/Users/monstar/Envs/Spider/lib/python3.6/site-packages/twisted/_threads/_threadworker.py:46:work
/Users/monstar/Envs/Spider/lib/python3.6/site-packages/twisted/_threads/_team.py:190:doWork
--- <exception caught here> ---
/Users/monstar/Envs/Spider/lib/python3.6/site-packages/twisted/python/threadpool.py:250:inContext
/Users/monstar/Envs/Spider/lib/python3.6/site-packages/twisted/python/threadpool.py:266:<lambda>
/Users/monstar/Envs/Spider/lib/python3.6/site-packages/twisted/python/context.py:122:callWithContext
/Users/monstar/Envs/Spider/lib/python3.6/site-packages/twisted/python/context.py:85:callWithContext
/Users/monstar/Envs/Spider/lib/python3.6/site-packages/twisted/enterprise/adbapi.py:477:_runInteraction
/Users/monstar/Envs/Spider/lib/python3.6/site-packages/twisted/python/compat.py:477:reraise
/Users/monstar/Envs/Spider/lib/python3.6/site-packages/twisted/enterprise/adbapi.py:467:_runInteraction
/Users/monstar/Desktop/ProjectCode/bigdatarecruit/SpiderMan/RecruitSpider/RecruitSpider/pipelines.py:105:do_insert_company
/Users/monstar/Envs/Spider/lib/python3.6/site-packages/MySQLdb/cursors.py:250:execute
/Users/monstar/Envs/Spider/lib/python3.6/site-packages/MySQLdb/connections.py:50:defaulterrorhandler
/Users/monstar/Envs/Spider/lib/python3.6/site-packages/MySQLdb/cursors.py:247:execute
/Users/monstar/Envs/Spider/lib/python3.6/site-packages/MySQLdb/cursors.py:411:_query
/Users/monstar/Envs/Spider/lib/python3.6/site-packages/MySQLdb/cursors.py:374:_do_query
/Users/monstar/Envs/Spider/lib/python3.6/site-packages/MySQLdb/connections.py:292:query
]2017-10-16 17:12:29
[Failure instance: Traceback: <class 'KeyError'>: 'industry'
/usr/local/Cellar/python3/3.6.1/Frameworks/Python.framework/Versions/3.6/lib/python3.6/threading.py:916:_bootstrap_inner
/usr/local/Cellar/python3/3.6.1/Frameworks/Python.framework/Versions/3.6/lib/python3.6/threading.py:864:run
/Users/monstar/Envs/Spider/lib/python3.6/site-packages/twisted/_threads/_threadworker.py:46:work
/Users/monstar/Envs/Spider/lib/python3.6/site-packages/twisted/_threads/_team.py:190:doWork
--- <exception caught here> ---
/Users/monstar/Envs/Spider/lib/python3.6/site-packages/twisted/python/threadpool.py:250:inContext
/Users/monstar/Envs/Spider/lib/python3.6/site-packages/twisted/python/threadpool.py:266:<lambda>
/Users/monstar/Envs/Spider/lib/python3.6/site-packages/twisted/python/context.py:122:callWithContext
/Users/monstar/Envs/Spider/lib/python3.6/site-packages/twisted/python/context.py:85:callWithContext
/Users/monstar/Envs/Spider/lib/python3.6/site-packages/twisted/enterprise/adbapi.py:477:_runInteraction
/Users/monstar/Envs/Spider/lib/python3.6/site-packages/twisted/python/compat.py:477:reraise
/Users/monstar/Envs/Spider/lib/python3.6/site-packages/twisted/enterprise/adbapi.py:467:_runInteraction
/Users/monstar/Desktop/ProjectCode/bigdatarecruit/SpiderMan/RecruitSpider/RecruitSpider/pipelines.py:104:do_insert_company
/Users/monstar/Desktop/ProjectCode/bigdatarecruit/SpiderMan/RecruitSpider/RecruitSpider/items.py:221:get_zhilian_company_insert_sql
/Users/monstar/Envs/Spider/lib/python3.6/site-packages/scrapy/item.py:59:__getitem__
]2017-10-16 17:12:29
[Failure instance: Traceback: <class '_mysql_exceptions.ProgrammingError'>: (1146, "Table 'spider.zhilian_position' doesn't exist")
/usr/local/Cellar/python3/3.6.1/Frameworks/Python.framework/Versions/3.6/lib/python3.6/threading.py:916:_bootstrap_inner
/usr/local/Cellar/python3/3.6.1/Frameworks/Python.framework/Versions/3.6/lib/python3.6/threading.py:864:run
/Users/monstar/Envs/Spider/lib/python3.6/site-packages/twisted/_threads/_threadworker.py:46:work
/Users/monstar/Envs/Spider/lib/python3.6/site-packages/twisted/_threads/_team.py:190:doWork
--- <exception caught here> ---
/Users/monstar/Envs/Spider/lib/python3.6/site-packages/twisted/python/threadpool.py:250:inContext
/Users/monstar/Envs/Spider/lib/python3.6/site-packages/twisted/python/threadpool.py:266:<lambda>
/Users/monstar/Envs/Spider/lib/python3.6/site-packages/twisted/python/context.py:122:callWithContext
/Users/monstar/Envs/Spider/lib/python3.6/site-packages/twisted/python/context.py:85:callWithContext
/Users/monstar/Envs/Spider/lib/python3.6/site-packages/twisted/enterprise/adbapi.py:477:_runInteraction
/Users/monstar/Envs/Spider/lib/python3.6/site-packages/twisted/python/compat.py:477:reraise
/Users/monstar/Envs/Spider/lib/python3.6/site-packages/twisted/enterprise/adbapi.py:467:_runInteraction
/Users/monstar/Desktop/ProjectCode/bigdatarecruit/SpiderMan/RecruitSpider/RecruitSpider/pipelines.py:109:do_insert_position
/Users/monstar/Envs/Spider/lib/python3.6/site-packages/MySQLdb/cursors.py:250:execute
/Users/monstar/Envs/Spider/lib/python3.6/site-packages/MySQLdb/connections.py:50:defaulterrorhandler
/Users/monstar/Envs/Spider/lib/python3.6/site-packages/MySQLdb/cursors.py:247:execute
/Users/monstar/Envs/Spider/lib/python3.6/site-packages/MySQLdb/cursors.py:411:_query
/Users/monstar/Envs/Spider/lib/python3.6/site-packages/MySQLdb/cursors.py:374:_do_query
/Users/monstar/Envs/Spider/lib/python3.6/site-packages/MySQLdb/connections.py:292:query
]2017-10-16 17:12:30
[Failure instance: Traceback: <class '_mysql_exceptions.ProgrammingError'>: (1146, "Table 'spider.zhilian_company' doesn't exist")
/usr/local/Cellar/python3/3.6.1/Frameworks/Python.framework/Versions/3.6/lib/python3.6/threading.py:916:_bootstrap_inner
/usr/local/Cellar/python3/3.6.1/Frameworks/Python.framework/Versions/3.6/lib/python3.6/threading.py:864:run
/Users/monstar/Envs/Spider/lib/python3.6/site-packages/twisted/_threads/_threadworker.py:46:work
/Users/monstar/Envs/Spider/lib/python3.6/site-packages/twisted/_threads/_team.py:190:doWork
--- <exception caught here> ---
/Users/monstar/Envs/Spider/lib/python3.6/site-packages/twisted/python/threadpool.py:250:inContext
/Users/monstar/Envs/Spider/lib/python3.6/site-packages/twisted/python/threadpool.py:266:<lambda>
/Users/monstar/Envs/Spider/lib/python3.6/site-packages/twisted/python/context.py:122:callWithContext
/Users/monstar/Envs/Spider/lib/python3.6/site-packages/twisted/python/context.py:85:callWithContext
/Users/monstar/Envs/Spider/lib/python3.6/site-packages/twisted/enterprise/adbapi.py:477:_runInteraction
/Users/monstar/Envs/Spider/lib/python3.6/site-packages/twisted/python/compat.py:477:reraise
/Users/monstar/Envs/Spider/lib/python3.6/site-packages/twisted/enterprise/adbapi.py:467:_runInteraction
/Users/monstar/Desktop/ProjectCode/bigdatarecruit/SpiderMan/RecruitSpider/RecruitSpider/pipelines.py:105:do_insert_company
/Users/monstar/Envs/Spider/lib/python3.6/site-packages/MySQLdb/cursors.py:250:execute
/Users/monstar/Envs/Spider/lib/python3.6/site-packages/MySQLdb/connections.py:50:defaulterrorhandler
/Users/monstar/Envs/Spider/lib/python3.6/site-packages/MySQLdb/cursors.py:247:execute
/Users/monstar/Envs/Spider/lib/python3.6/site-packages/MySQLdb/cursors.py:411:_query
/Users/monstar/Envs/Spider/lib/python3.6/site-packages/MySQLdb/cursors.py:374:_do_query
/Users/monstar/Envs/Spider/lib/python3.6/site-packages/MySQLdb/connections.py:292:query
]2017-10-16 17:12:30
[Failure instance: Traceback: <class '_mysql_exceptions.ProgrammingError'>: (1146, "Table 'spider.zhilian_position' doesn't exist")
/usr/local/Cellar/python3/3.6.1/Frameworks/Python.framework/Versions/3.6/lib/python3.6/threading.py:916:_bootstrap_inner
/usr/local/Cellar/python3/3.6.1/Frameworks/Python.framework/Versions/3.6/lib/python3.6/threading.py:864:run
/Users/monstar/Envs/Spider/lib/python3.6/site-packages/twisted/_threads/_threadworker.py:46:work
/Users/monstar/Envs/Spider/lib/python3.6/site-packages/twisted/_threads/_team.py:190:doWork
--- <exception caught here> ---
/Users/monstar/Envs/Spider/lib/python3.6/site-packages/twisted/python/threadpool.py:250:inContext
/Users/monstar/Envs/Spider/lib/python3.6/site-packages/twisted/python/threadpool.py:266:<lambda>
/Users/monstar/Envs/Spider/lib/python3.6/site-packages/twisted/python/context.py:122:callWithContext
/Users/monstar/Envs/Spider/lib/python3.6/site-packages/twisted/python/context.py:85:callWithContext
/Users/monstar/Envs/Spider/lib/python3.6/site-packages/twisted/enterprise/adbapi.py:477:_runInteraction
/Users/monstar/Envs/Spider/lib/python3.6/site-packages/twisted/python/compat.py:477:reraise
/Users/monstar/Envs/Spider/lib/python3.6/site-packages/twisted/enterprise/adbapi.py:467:_runInteraction
/Users/monstar/Desktop/ProjectCode/bigdatarecruit/SpiderMan/RecruitSpider/RecruitSpider/pipelines.py:109:do_insert_position
/Users/monstar/Envs/Spider/lib/python3.6/site-packages/MySQLdb/cursors.py:250:execute
/Users/monstar/Envs/Spider/lib/python3.6/site-packages/MySQLdb/connections.py:50:defaulterrorhandler
/Users/monstar/Envs/Spider/lib/python3.6/site-packages/MySQLdb/cursors.py:247:execute
/Users/monstar/Envs/Spider/lib/python3.6/site-packages/MySQLdb/cursors.py:411:_query
/Users/monstar/Envs/Spider/lib/python3.6/site-packages/MySQLdb/cursors.py:374:_do_query
/Users/monstar/Envs/Spider/lib/python3.6/site-packages/MySQLdb/connections.py:292:query
]2017-10-16 17:13:39
[Failure instance: Traceback: <class '_mysql_exceptions.ProgrammingError'>: (1110, "Column 'industry' specified twice")
/usr/local/Cellar/python3/3.6.1/Frameworks/Python.framework/Versions/3.6/lib/python3.6/threading.py:916:_bootstrap_inner
/usr/local/Cellar/python3/3.6.1/Frameworks/Python.framework/Versions/3.6/lib/python3.6/threading.py:864:run
/Users/monstar/Envs/Spider/lib/python3.6/site-packages/twisted/_threads/_threadworker.py:46:work
/Users/monstar/Envs/Spider/lib/python3.6/site-packages/twisted/_threads/_team.py:190:doWork
--- <exception caught here> ---
/Users/monstar/Envs/Spider/lib/python3.6/site-packages/twisted/python/threadpool.py:250:inContext
/Users/monstar/Envs/Spider/lib/python3.6/site-packages/twisted/python/threadpool.py:266:<lambda>
/Users/monstar/Envs/Spider/lib/python3.6/site-packages/twisted/python/context.py:122:callWithContext
/Users/monstar/Envs/Spider/lib/python3.6/site-packages/twisted/python/context.py:85:callWithContext
/Users/monstar/Envs/Spider/lib/python3.6/site-packages/twisted/enterprise/adbapi.py:477:_runInteraction
/Users/monstar/Envs/Spider/lib/python3.6/site-packages/twisted/python/compat.py:477:reraise
/Users/monstar/Envs/Spider/lib/python3.6/site-packages/twisted/enterprise/adbapi.py:467:_runInteraction
/Users/monstar/Desktop/ProjectCode/bigdatarecruit/SpiderMan/RecruitSpider/RecruitSpider/pipelines.py:105:do_insert_company
/Users/monstar/Envs/Spider/lib/python3.6/site-packages/MySQLdb/cursors.py:250:execute
/Users/monstar/Envs/Spider/lib/python3.6/site-packages/MySQLdb/connections.py:50:defaulterrorhandler
/Users/monstar/Envs/Spider/lib/python3.6/site-packages/MySQLdb/cursors.py:247:execute
/Users/monstar/Envs/Spider/lib/python3.6/site-packages/MySQLdb/cursors.py:411:_query
/Users/monstar/Envs/Spider/lib/python3.6/site-packages/MySQLdb/cursors.py:374:_do_query
/Users/monstar/Envs/Spider/lib/python3.6/site-packages/MySQLdb/connections.py:292:query
]2017-10-16 17:13:39
[Failure instance: Traceback: <class '_mysql_exceptions.OperationalError'>: (1054, "Unknown column 'position_name' in 'field list'")
/usr/local/Cellar/python3/3.6.1/Frameworks/Python.framework/Versions/3.6/lib/python3.6/threading.py:916:_bootstrap_inner
/usr/local/Cellar/python3/3.6.1/Frameworks/Python.framework/Versions/3.6/lib/python3.6/threading.py:864:run
/Users/monstar/Envs/Spider/lib/python3.6/site-packages/twisted/_threads/_threadworker.py:46:work
/Users/monstar/Envs/Spider/lib/python3.6/site-packages/twisted/_threads/_team.py:190:doWork
--- <exception caught here> ---
/Users/monstar/Envs/Spider/lib/python3.6/site-packages/twisted/python/threadpool.py:250:inContext
/Users/monstar/Envs/Spider/lib/python3.6/site-packages/twisted/python/threadpool.py:266:<lambda>
/Users/monstar/Envs/Spider/lib/python3.6/site-packages/twisted/python/context.py:122:callWithContext
/Users/monstar/Envs/Spider/lib/python3.6/site-packages/twisted/python/context.py:85:callWithContext
/Users/monstar/Envs/Spider/lib/python3.6/site-packages/twisted/enterprise/adbapi.py:477:_runInteraction
/Users/monstar/Envs/Spider/lib/python3.6/site-packages/twisted/python/compat.py:477:reraise
/Users/monstar/Envs/Spider/lib/python3.6/site-packages/twisted/enterprise/adbapi.py:467:_runInteraction
/Users/monstar/Desktop/ProjectCode/bigdatarecruit/SpiderMan/RecruitSpider/RecruitSpider/pipelines.py:109:do_insert_position
/Users/monstar/Envs/Spider/lib/python3.6/site-packages/MySQLdb/cursors.py:250:execute
/Users/monstar/Envs/Spider/lib/python3.6/site-packages/MySQLdb/connections.py:50:defaulterrorhandler
/Users/monstar/Envs/Spider/lib/python3.6/site-packages/MySQLdb/cursors.py:247:execute
/Users/monstar/Envs/Spider/lib/python3.6/site-packages/MySQLdb/cursors.py:411:_query
/Users/monstar/Envs/Spider/lib/python3.6/site-packages/MySQLdb/cursors.py:374:_do_query
/Users/monstar/Envs/Spider/lib/python3.6/site-packages/MySQLdb/connections.py:292:query
]2017-10-16 17:13:41
[Failure instance: Traceback: <class 'KeyError'>: 'industry'
/usr/local/Cellar/python3/3.6.1/Frameworks/Python.framework/Versions/3.6/lib/python3.6/threading.py:916:_bootstrap_inner
/usr/local/Cellar/python3/3.6.1/Frameworks/Python.framework/Versions/3.6/lib/python3.6/threading.py:864:run
/Users/monstar/Envs/Spider/lib/python3.6/site-packages/twisted/_threads/_threadworker.py:46:work
/Users/monstar/Envs/Spider/lib/python3.6/site-packages/twisted/_threads/_team.py:190:doWork
--- <exception caught here> ---
/Users/monstar/Envs/Spider/lib/python3.6/site-packages/twisted/python/threadpool.py:250:inContext
/Users/monstar/Envs/Spider/lib/python3.6/site-packages/twisted/python/threadpool.py:266:<lambda>
/Users/monstar/Envs/Spider/lib/python3.6/site-packages/twisted/python/context.py:122:callWithContext
/Users/monstar/Envs/Spider/lib/python3.6/site-packages/twisted/python/context.py:85:callWithContext
/Users/monstar/Envs/Spider/lib/python3.6/site-packages/twisted/enterprise/adbapi.py:477:_runInteraction
/Users/monstar/Envs/Spider/lib/python3.6/site-packages/twisted/python/compat.py:477:reraise
/Users/monstar/Envs/Spider/lib/python3.6/site-packages/twisted/enterprise/adbapi.py:467:_runInteraction
/Users/monstar/Desktop/ProjectCode/bigdatarecruit/SpiderMan/RecruitSpider/RecruitSpider/pipelines.py:104:do_insert_company
/Users/monstar/Desktop/ProjectCode/bigdatarecruit/SpiderMan/RecruitSpider/RecruitSpider/items.py:221:get_zhilian_company_insert_sql
/Users/monstar/Envs/Spider/lib/python3.6/site-packages/scrapy/item.py:59:__getitem__
]2017-10-16 17:13:41
[Failure instance: Traceback: <class '_mysql_exceptions.OperationalError'>: (1054, "Unknown column 'position_name' in 'field list'")
/usr/local/Cellar/python3/3.6.1/Frameworks/Python.framework/Versions/3.6/lib/python3.6/threading.py:916:_bootstrap_inner
/usr/local/Cellar/python3/3.6.1/Frameworks/Python.framework/Versions/3.6/lib/python3.6/threading.py:864:run
/Users/monstar/Envs/Spider/lib/python3.6/site-packages/twisted/_threads/_threadworker.py:46:work
/Users/monstar/Envs/Spider/lib/python3.6/site-packages/twisted/_threads/_team.py:190:doWork
--- <exception caught here> ---
/Users/monstar/Envs/Spider/lib/python3.6/site-packages/twisted/python/threadpool.py:250:inContext
/Users/monstar/Envs/Spider/lib/python3.6/site-packages/twisted/python/threadpool.py:266:<lambda>
/Users/monstar/Envs/Spider/lib/python3.6/site-packages/twisted/python/context.py:122:callWithContext
/Users/monstar/Envs/Spider/lib/python3.6/site-packages/twisted/python/context.py:85:callWithContext
/Users/monstar/Envs/Spider/lib/python3.6/site-packages/twisted/enterprise/adbapi.py:477:_runInteraction
/Users/monstar/Envs/Spider/lib/python3.6/site-packages/twisted/python/compat.py:477:reraise
/Users/monstar/Envs/Spider/lib/python3.6/site-packages/twisted/enterprise/adbapi.py:467:_runInteraction
/Users/monstar/Desktop/ProjectCode/bigdatarecruit/SpiderMan/RecruitSpider/RecruitSpider/pipelines.py:109:do_insert_position
/Users/monstar/Envs/Spider/lib/python3.6/site-packages/MySQLdb/cursors.py:250:execute
/Users/monstar/Envs/Spider/lib/python3.6/site-packages/MySQLdb/connections.py:50:defaulterrorhandler
/Users/monstar/Envs/Spider/lib/python3.6/site-packages/MySQLdb/cursors.py:247:execute
/Users/monstar/Envs/Spider/lib/python3.6/site-packages/MySQLdb/cursors.py:411:_query
/Users/monstar/Envs/Spider/lib/python3.6/site-packages/MySQLdb/cursors.py:374:_do_query
/Users/monstar/Envs/Spider/lib/python3.6/site-packages/MySQLdb/connections.py:292:query
]2017-10-16 17:13:41
[Failure instance: Traceback: <class '_mysql_exceptions.OperationalError'>: (1054, "Unknown column 'position_name' in 'field list'")
/usr/local/Cellar/python3/3.6.1/Frameworks/Python.framework/Versions/3.6/lib/python3.6/threading.py:916:_bootstrap_inner
/usr/local/Cellar/python3/3.6.1/Frameworks/Python.framework/Versions/3.6/lib/python3.6/threading.py:864:run
/Users/monstar/Envs/Spider/lib/python3.6/site-packages/twisted/_threads/_threadworker.py:46:work
/Users/monstar/Envs/Spider/lib/python3.6/site-packages/twisted/_threads/_team.py:190:doWork
--- <exception caught here> ---
/Users/monstar/Envs/Spider/lib/python3.6/site-packages/twisted/python/threadpool.py:250:inContext
/Users/monstar/Envs/Spider/lib/python3.6/site-packages/twisted/python/threadpool.py:266:<lambda>
/Users/monstar/Envs/Spider/lib/python3.6/site-packages/twisted/python/context.py:122:callWithContext
/Users/monstar/Envs/Spider/lib/python3.6/site-packages/twisted/python/context.py:85:callWithContext
/Users/monstar/Envs/Spider/lib/python3.6/site-packages/twisted/enterprise/adbapi.py:477:_runInteraction
/Users/monstar/Envs/Spider/lib/python3.6/site-packages/twisted/python/compat.py:477:reraise
/Users/monstar/Envs/Spider/lib/python3.6/site-packages/twisted/enterprise/adbapi.py:467:_runInteraction
/Users/monstar/Desktop/ProjectCode/bigdatarecruit/SpiderMan/RecruitSpider/RecruitSpider/pipelines.py:109:do_insert_position
/Users/monstar/Envs/Spider/lib/python3.6/site-packages/MySQLdb/cursors.py:250:execute
/Users/monstar/Envs/Spider/lib/python3.6/site-packages/MySQLdb/connections.py:50:defaulterrorhandler
/Users/monstar/Envs/Spider/lib/python3.6/site-packages/MySQLdb/cursors.py:247:execute
/Users/monstar/Envs/Spider/lib/python3.6/site-packages/MySQLdb/cursors.py:411:_query
/Users/monstar/Envs/Spider/lib/python3.6/site-packages/MySQLdb/cursors.py:374:_do_query
/Users/monstar/Envs/Spider/lib/python3.6/site-packages/MySQLdb/connections.py:292:query
]2017-10-16 17:13:41
[Failure instance: Traceback: <class '_mysql_exceptions.ProgrammingError'>: (1110, "Column 'industry' specified twice")
/usr/local/Cellar/python3/3.6.1/Frameworks/Python.framework/Versions/3.6/lib/python3.6/threading.py:916:_bootstrap_inner
/usr/local/Cellar/python3/3.6.1/Frameworks/Python.framework/Versions/3.6/lib/python3.6/threading.py:864:run
/Users/monstar/Envs/Spider/lib/python3.6/site-packages/twisted/_threads/_threadworker.py:46:work
/Users/monstar/Envs/Spider/lib/python3.6/site-packages/twisted/_threads/_team.py:190:doWork
--- <exception caught here> ---
/Users/monstar/Envs/Spider/lib/python3.6/site-packages/twisted/python/threadpool.py:250:inContext
/Users/monstar/Envs/Spider/lib/python3.6/site-packages/twisted/python/threadpool.py:266:<lambda>
/Users/monstar/Envs/Spider/lib/python3.6/site-packages/twisted/python/context.py:122:callWithContext
/Users/monstar/Envs/Spider/lib/python3.6/site-packages/twisted/python/context.py:85:callWithContext
/Users/monstar/Envs/Spider/lib/python3.6/site-packages/twisted/enterprise/adbapi.py:477:_runInteraction
/Users/monstar/Envs/Spider/lib/python3.6/site-packages/twisted/python/compat.py:477:reraise
/Users/monstar/Envs/Spider/lib/python3.6/site-packages/twisted/enterprise/adbapi.py:467:_runInteraction
/Users/monstar/Desktop/ProjectCode/bigdatarecruit/SpiderMan/RecruitSpider/RecruitSpider/pipelines.py:105:do_insert_company
/Users/monstar/Envs/Spider/lib/python3.6/site-packages/MySQLdb/cursors.py:250:execute
/Users/monstar/Envs/Spider/lib/python3.6/site-packages/MySQLdb/connections.py:50:defaulterrorhandler
/Users/monstar/Envs/Spider/lib/python3.6/site-packages/MySQLdb/cursors.py:247:execute
/Users/monstar/Envs/Spider/lib/python3.6/site-packages/MySQLdb/cursors.py:411:_query
/Users/monstar/Envs/Spider/lib/python3.6/site-packages/MySQLdb/cursors.py:374:_do_query
/Users/monstar/Envs/Spider/lib/python3.6/site-packages/MySQLdb/connections.py:292:query
]2017-10-16 17:24:14
[Failure instance: Traceback: <class '_mysql_exceptions.OperationalError'>: (1054, "Unknown column 'position_name' in 'field list'")
/usr/local/Cellar/python3/3.6.1/Frameworks/Python.framework/Versions/3.6/lib/python3.6/threading.py:916:_bootstrap_inner
/usr/local/Cellar/python3/3.6.1/Frameworks/Python.framework/Versions/3.6/lib/python3.6/threading.py:864:run
/Users/monstar/Envs/Spider/lib/python3.6/site-packages/twisted/_threads/_threadworker.py:46:work
/Users/monstar/Envs/Spider/lib/python3.6/site-packages/twisted/_threads/_team.py:190:doWork
--- <exception caught here> ---
/Users/monstar/Envs/Spider/lib/python3.6/site-packages/twisted/python/threadpool.py:250:inContext
/Users/monstar/Envs/Spider/lib/python3.6/site-packages/twisted/python/threadpool.py:266:<lambda>
/Users/monstar/Envs/Spider/lib/python3.6/site-packages/twisted/python/context.py:122:callWithContext
/Users/monstar/Envs/Spider/lib/python3.6/site-packages/twisted/python/context.py:85:callWithContext
/Users/monstar/Envs/Spider/lib/python3.6/site-packages/twisted/enterprise/adbapi.py:477:_runInteraction
/Users/monstar/Envs/Spider/lib/python3.6/site-packages/twisted/python/compat.py:477:reraise
/Users/monstar/Envs/Spider/lib/python3.6/site-packages/twisted/enterprise/adbapi.py:467:_runInteraction
/Users/monstar/Desktop/ProjectCode/bigdatarecruit/SpiderMan/RecruitSpider/RecruitSpider/pipelines.py:109:do_insert_position
/Users/monstar/Envs/Spider/lib/python3.6/site-packages/MySQLdb/cursors.py:250:execute
/Users/monstar/Envs/Spider/lib/python3.6/site-packages/MySQLdb/connections.py:50:defaulterrorhandler
/Users/monstar/Envs/Spider/lib/python3.6/site-packages/MySQLdb/cursors.py:247:execute
/Users/monstar/Envs/Spider/lib/python3.6/site-packages/MySQLdb/cursors.py:411:_query
/Users/monstar/Envs/Spider/lib/python3.6/site-packages/MySQLdb/cursors.py:374:_do_query
/Users/monstar/Envs/Spider/lib/python3.6/site-packages/MySQLdb/connections.py:292:query
]2017-10-16 17:24:15
[Failure instance: Traceback: <class '_mysql_exceptions.OperationalError'>: (1054, "Unknown column 'position_name' in 'field list'")
/usr/local/Cellar/python3/3.6.1/Frameworks/Python.framework/Versions/3.6/lib/python3.6/threading.py:916:_bootstrap_inner
/usr/local/Cellar/python3/3.6.1/Frameworks/Python.framework/Versions/3.6/lib/python3.6/threading.py:864:run
/Users/monstar/Envs/Spider/lib/python3.6/site-packages/twisted/_threads/_threadworker.py:46:work
/Users/monstar/Envs/Spider/lib/python3.6/site-packages/twisted/_threads/_team.py:190:doWork
--- <exception caught here> ---
/Users/monstar/Envs/Spider/lib/python3.6/site-packages/twisted/python/threadpool.py:250:inContext
/Users/monstar/Envs/Spider/lib/python3.6/site-packages/twisted/python/threadpool.py:266:<lambda>
/Users/monstar/Envs/Spider/lib/python3.6/site-packages/twisted/python/context.py:122:callWithContext
/Users/monstar/Envs/Spider/lib/python3.6/site-packages/twisted/python/context.py:85:callWithContext
/Users/monstar/Envs/Spider/lib/python3.6/site-packages/twisted/enterprise/adbapi.py:477:_runInteraction
/Users/monstar/Envs/Spider/lib/python3.6/site-packages/twisted/python/compat.py:477:reraise
/Users/monstar/Envs/Spider/lib/python3.6/site-packages/twisted/enterprise/adbapi.py:467:_runInteraction
/Users/monstar/Desktop/ProjectCode/bigdatarecruit/SpiderMan/RecruitSpider/RecruitSpider/pipelines.py:109:do_insert_position
/Users/monstar/Envs/Spider/lib/python3.6/site-packages/MySQLdb/cursors.py:250:execute
/Users/monstar/Envs/Spider/lib/python3.6/site-packages/MySQLdb/connections.py:50:defaulterrorhandler
/Users/monstar/Envs/Spider/lib/python3.6/site-packages/MySQLdb/cursors.py:247:execute
/Users/monstar/Envs/Spider/lib/python3.6/site-packages/MySQLdb/cursors.py:411:_query
/Users/monstar/Envs/Spider/lib/python3.6/site-packages/MySQLdb/cursors.py:374:_do_query
/Users/monstar/Envs/Spider/lib/python3.6/site-packages/MySQLdb/connections.py:292:query
]2017-10-16 17:26:22
[Failure instance: Traceback: <class '_mysql_exceptions.DataError'>: (1265, "Data truncated for column 'salary_low' at row 1")
/usr/local/Cellar/python3/3.6.1/Frameworks/Python.framework/Versions/3.6/lib/python3.6/threading.py:916:_bootstrap_inner
/usr/local/Cellar/python3/3.6.1/Frameworks/Python.framework/Versions/3.6/lib/python3.6/threading.py:864:run
/Users/monstar/Envs/Spider/lib/python3.6/site-packages/twisted/_threads/_threadworker.py:46:work
/Users/monstar/Envs/Spider/lib/python3.6/site-packages/twisted/_threads/_team.py:190:doWork
--- <exception caught here> ---
/Users/monstar/Envs/Spider/lib/python3.6/site-packages/twisted/python/threadpool.py:250:inContext
/Users/monstar/Envs/Spider/lib/python3.6/site-packages/twisted/python/threadpool.py:266:<lambda>
/Users/monstar/Envs/Spider/lib/python3.6/site-packages/twisted/python/context.py:122:callWithContext
/Users/monstar/Envs/Spider/lib/python3.6/site-packages/twisted/python/context.py:85:callWithContext
/Users/monstar/Envs/Spider/lib/python3.6/site-packages/twisted/enterprise/adbapi.py:477:_runInteraction
/Users/monstar/Envs/Spider/lib/python3.6/site-packages/twisted/python/compat.py:477:reraise
/Users/monstar/Envs/Spider/lib/python3.6/site-packages/twisted/enterprise/adbapi.py:467:_runInteraction
/Users/monstar/Desktop/ProjectCode/bigdatarecruit/SpiderMan/RecruitSpider/RecruitSpider/pipelines.py:109:do_insert_position
/Users/monstar/Envs/Spider/lib/python3.6/site-packages/MySQLdb/cursors.py:250:execute
/Users/monstar/Envs/Spider/lib/python3.6/site-packages/MySQLdb/connections.py:50:defaulterrorhandler
/Users/monstar/Envs/Spider/lib/python3.6/site-packages/MySQLdb/cursors.py:247:execute
/Users/monstar/Envs/Spider/lib/python3.6/site-packages/MySQLdb/cursors.py:411:_query
/Users/monstar/Envs/Spider/lib/python3.6/site-packages/MySQLdb/cursors.py:374:_do_query
/Users/monstar/Envs/Spider/lib/python3.6/site-packages/MySQLdb/connections.py:292:query
]2017-10-16 17:26:24
[Failure instance: Traceback: <class '_mysql_exceptions.DataError'>: (1265, "Data truncated for column 'salary_low' at row 1")
/usr/local/Cellar/python3/3.6.1/Frameworks/Python.framework/Versions/3.6/lib/python3.6/threading.py:916:_bootstrap_inner
/usr/local/Cellar/python3/3.6.1/Frameworks/Python.framework/Versions/3.6/lib/python3.6/threading.py:864:run
/Users/monstar/Envs/Spider/lib/python3.6/site-packages/twisted/_threads/_threadworker.py:46:work
/Users/monstar/Envs/Spider/lib/python3.6/site-packages/twisted/_threads/_team.py:190:doWork
--- <exception caught here> ---
/Users/monstar/Envs/Spider/lib/python3.6/site-packages/twisted/python/threadpool.py:250:inContext
/Users/monstar/Envs/Spider/lib/python3.6/site-packages/twisted/python/threadpool.py:266:<lambda>
/Users/monstar/Envs/Spider/lib/python3.6/site-packages/twisted/python/context.py:122:callWithContext
/Users/monstar/Envs/Spider/lib/python3.6/site-packages/twisted/python/context.py:85:callWithContext
/Users/monstar/Envs/Spider/lib/python3.6/site-packages/twisted/enterprise/adbapi.py:477:_runInteraction
/Users/monstar/Envs/Spider/lib/python3.6/site-packages/twisted/python/compat.py:477:reraise
/Users/monstar/Envs/Spider/lib/python3.6/site-packages/twisted/enterprise/adbapi.py:467:_runInteraction
/Users/monstar/Desktop/ProjectCode/bigdatarecruit/SpiderMan/RecruitSpider/RecruitSpider/pipelines.py:109:do_insert_position
/Users/monstar/Envs/Spider/lib/python3.6/site-packages/MySQLdb/cursors.py:250:execute
/Users/monstar/Envs/Spider/lib/python3.6/site-packages/MySQLdb/connections.py:50:defaulterrorhandler
/Users/monstar/Envs/Spider/lib/python3.6/site-packages/MySQLdb/cursors.py:247:execute
/Users/monstar/Envs/Spider/lib/python3.6/site-packages/MySQLdb/cursors.py:411:_query
/Users/monstar/Envs/Spider/lib/python3.6/site-packages/MySQLdb/cursors.py:374:_do_query
/Users/monstar/Envs/Spider/lib/python3.6/site-packages/MySQLdb/connections.py:292:query
]2017-10-16 17:26:25
[Failure instance: Traceback: <class '_mysql_exceptions.DataError'>: (1265, "Data truncated for column 'salary_low' at row 1")
/usr/local/Cellar/python3/3.6.1/Frameworks/Python.framework/Versions/3.6/lib/python3.6/threading.py:916:_bootstrap_inner
/usr/local/Cellar/python3/3.6.1/Frameworks/Python.framework/Versions/3.6/lib/python3.6/threading.py:864:run
/Users/monstar/Envs/Spider/lib/python3.6/site-packages/twisted/_threads/_threadworker.py:46:work
/Users/monstar/Envs/Spider/lib/python3.6/site-packages/twisted/_threads/_team.py:190:doWork
--- <exception caught here> ---
/Users/monstar/Envs/Spider/lib/python3.6/site-packages/twisted/python/threadpool.py:250:inContext
/Users/monstar/Envs/Spider/lib/python3.6/site-packages/twisted/python/threadpool.py:266:<lambda>
/Users/monstar/Envs/Spider/lib/python3.6/site-packages/twisted/python/context.py:122:callWithContext
/Users/monstar/Envs/Spider/lib/python3.6/site-packages/twisted/python/context.py:85:callWithContext
/Users/monstar/Envs/Spider/lib/python3.6/site-packages/twisted/enterprise/adbapi.py:477:_runInteraction
/Users/monstar/Envs/Spider/lib/python3.6/site-packages/twisted/python/compat.py:477:reraise
/Users/monstar/Envs/Spider/lib/python3.6/site-packages/twisted/enterprise/adbapi.py:467:_runInteraction
/Users/monstar/Desktop/ProjectCode/bigdatarecruit/SpiderMan/RecruitSpider/RecruitSpider/pipelines.py:109:do_insert_position
/Users/monstar/Envs/Spider/lib/python3.6/site-packages/MySQLdb/cursors.py:250:execute
/Users/monstar/Envs/Spider/lib/python3.6/site-packages/MySQLdb/connections.py:50:defaulterrorhandler
/Users/monstar/Envs/Spider/lib/python3.6/site-packages/MySQLdb/cursors.py:247:execute
/Users/monstar/Envs/Spider/lib/python3.6/site-packages/MySQLdb/cursors.py:411:_query
/Users/monstar/Envs/Spider/lib/python3.6/site-packages/MySQLdb/cursors.py:374:_do_query
/Users/monstar/Envs/Spider/lib/python3.6/site-packages/MySQLdb/connections.py:292:query
]2017-10-16 17:28:32
[Failure instance: Traceback: <class '_mysql_exceptions.DataError'>: (1265, "Data truncated for column 'salary_low' at row 1")
/usr/local/Cellar/python3/3.6.1/Frameworks/Python.framework/Versions/3.6/lib/python3.6/threading.py:916:_bootstrap_inner
/usr/local/Cellar/python3/3.6.1/Frameworks/Python.framework/Versions/3.6/lib/python3.6/threading.py:864:run
/Users/monstar/Envs/Spider/lib/python3.6/site-packages/twisted/_threads/_threadworker.py:46:work
/Users/monstar/Envs/Spider/lib/python3.6/site-packages/twisted/_threads/_team.py:190:doWork
--- <exception caught here> ---
/Users/monstar/Envs/Spider/lib/python3.6/site-packages/twisted/python/threadpool.py:250:inContext
/Users/monstar/Envs/Spider/lib/python3.6/site-packages/twisted/python/threadpool.py:266:<lambda>
/Users/monstar/Envs/Spider/lib/python3.6/site-packages/twisted/python/context.py:122:callWithContext
/Users/monstar/Envs/Spider/lib/python3.6/site-packages/twisted/python/context.py:85:callWithContext
/Users/monstar/Envs/Spider/lib/python3.6/site-packages/twisted/enterprise/adbapi.py:477:_runInteraction
/Users/monstar/Envs/Spider/lib/python3.6/site-packages/twisted/python/compat.py:477:reraise
/Users/monstar/Envs/Spider/lib/python3.6/site-packages/twisted/enterprise/adbapi.py:467:_runInteraction
/Users/monstar/Desktop/ProjectCode/bigdatarecruit/SpiderMan/RecruitSpider/RecruitSpider/pipelines.py:109:do_insert_position
/Users/monstar/Envs/Spider/lib/python3.6/site-packages/MySQLdb/cursors.py:250:execute
/Users/monstar/Envs/Spider/lib/python3.6/site-packages/MySQLdb/connections.py:50:defaulterrorhandler
/Users/monstar/Envs/Spider/lib/python3.6/site-packages/MySQLdb/cursors.py:247:execute
/Users/monstar/Envs/Spider/lib/python3.6/site-packages/MySQLdb/cursors.py:411:_query
/Users/monstar/Envs/Spider/lib/python3.6/site-packages/MySQLdb/cursors.py:374:_do_query
/Users/monstar/Envs/Spider/lib/python3.6/site-packages/MySQLdb/connections.py:292:query
]2017-10-16 17:28:33
[Failure instance: Traceback: <class 'KeyError'>: 'industry'
/usr/local/Cellar/python3/3.6.1/Frameworks/Python.framework/Versions/3.6/lib/python3.6/threading.py:916:_bootstrap_inner
/usr/local/Cellar/python3/3.6.1/Frameworks/Python.framework/Versions/3.6/lib/python3.6/threading.py:864:run
/Users/monstar/Envs/Spider/lib/python3.6/site-packages/twisted/_threads/_threadworker.py:46:work
/Users/monstar/Envs/Spider/lib/python3.6/site-packages/twisted/_threads/_team.py:190:doWork
--- <exception caught here> ---
/Users/monstar/Envs/Spider/lib/python3.6/site-packages/twisted/python/threadpool.py:250:inContext
/Users/monstar/Envs/Spider/lib/python3.6/site-packages/twisted/python/threadpool.py:266:<lambda>
/Users/monstar/Envs/Spider/lib/python3.6/site-packages/twisted/python/context.py:122:callWithContext
/Users/monstar/Envs/Spider/lib/python3.6/site-packages/twisted/python/context.py:85:callWithContext
/Users/monstar/Envs/Spider/lib/python3.6/site-packages/twisted/enterprise/adbapi.py:477:_runInteraction
/Users/monstar/Envs/Spider/lib/python3.6/site-packages/twisted/python/compat.py:477:reraise
/Users/monstar/Envs/Spider/lib/python3.6/site-packages/twisted/enterprise/adbapi.py:467:_runInteraction
/Users/monstar/Desktop/ProjectCode/bigdatarecruit/SpiderMan/RecruitSpider/RecruitSpider/pipelines.py:104:do_insert_company
/Users/monstar/Desktop/ProjectCode/bigdatarecruit/SpiderMan/RecruitSpider/RecruitSpider/items.py:221:get_zhilian_company_insert_sql
/Users/monstar/Envs/Spider/lib/python3.6/site-packages/scrapy/item.py:59:__getitem__
]2017-10-16 17:28:33
[Failure instance: Traceback: <class '_mysql_exceptions.DataError'>: (1265, "Data truncated for column 'salary_low' at row 1")
/usr/local/Cellar/python3/3.6.1/Frameworks/Python.framework/Versions/3.6/lib/python3.6/threading.py:916:_bootstrap_inner
/usr/local/Cellar/python3/3.6.1/Frameworks/Python.framework/Versions/3.6/lib/python3.6/threading.py:864:run
/Users/monstar/Envs/Spider/lib/python3.6/site-packages/twisted/_threads/_threadworker.py:46:work
/Users/monstar/Envs/Spider/lib/python3.6/site-packages/twisted/_threads/_team.py:190:doWork
--- <exception caught here> ---
/Users/monstar/Envs/Spider/lib/python3.6/site-packages/twisted/python/threadpool.py:250:inContext
/Users/monstar/Envs/Spider/lib/python3.6/site-packages/twisted/python/threadpool.py:266:<lambda>
/Users/monstar/Envs/Spider/lib/python3.6/site-packages/twisted/python/context.py:122:callWithContext
/Users/monstar/Envs/Spider/lib/python3.6/site-packages/twisted/python/context.py:85:callWithContext
/Users/monstar/Envs/Spider/lib/python3.6/site-packages/twisted/enterprise/adbapi.py:477:_runInteraction
/Users/monstar/Envs/Spider/lib/python3.6/site-packages/twisted/python/compat.py:477:reraise
/Users/monstar/Envs/Spider/lib/python3.6/site-packages/twisted/enterprise/adbapi.py:467:_runInteraction
/Users/monstar/Desktop/ProjectCode/bigdatarecruit/SpiderMan/RecruitSpider/RecruitSpider/pipelines.py:109:do_insert_position
/Users/monstar/Envs/Spider/lib/python3.6/site-packages/MySQLdb/cursors.py:250:execute
/Users/monstar/Envs/Spider/lib/python3.6/site-packages/MySQLdb/connections.py:50:defaulterrorhandler
/Users/monstar/Envs/Spider/lib/python3.6/site-packages/MySQLdb/cursors.py:247:execute
/Users/monstar/Envs/Spider/lib/python3.6/site-packages/MySQLdb/cursors.py:411:_query
/Users/monstar/Envs/Spider/lib/python3.6/site-packages/MySQLdb/cursors.py:374:_do_query
/Users/monstar/Envs/Spider/lib/python3.6/site-packages/MySQLdb/connections.py:292:query
]2017-10-16 17:55:03
[Failure instance: Traceback: <class 'KeyError'>: 'advantage_labels'
/usr/local/Cellar/python3/3.6.1/Frameworks/Python.framework/Versions/3.6/lib/python3.6/threading.py:916:_bootstrap_inner
/usr/local/Cellar/python3/3.6.1/Frameworks/Python.framework/Versions/3.6/lib/python3.6/threading.py:864:run
/Users/monstar/Envs/Spider/lib/python3.6/site-packages/twisted/_threads/_threadworker.py:46:work
/Users/monstar/Envs/Spider/lib/python3.6/site-packages/twisted/_threads/_team.py:190:doWork
--- <exception caught here> ---
/Users/monstar/Envs/Spider/lib/python3.6/site-packages/twisted/python/threadpool.py:250:inContext
/Users/monstar/Envs/Spider/lib/python3.6/site-packages/twisted/python/threadpool.py:266:<lambda>
/Users/monstar/Envs/Spider/lib/python3.6/site-packages/twisted/python/context.py:122:callWithContext
/Users/monstar/Envs/Spider/lib/python3.6/site-packages/twisted/python/context.py:85:callWithContext
/Users/monstar/Envs/Spider/lib/python3.6/site-packages/twisted/enterprise/adbapi.py:477:_runInteraction
/Users/monstar/Envs/Spider/lib/python3.6/site-packages/twisted/python/compat.py:477:reraise
/Users/monstar/Envs/Spider/lib/python3.6/site-packages/twisted/enterprise/adbapi.py:467:_runInteraction
/Users/monstar/Desktop/ProjectCode/bigdatarecruit/SpiderMan/RecruitSpider/RecruitSpider/pipelines.py:108:do_insert_position
/Users/monstar/Desktop/ProjectCode/bigdatarecruit/SpiderMan/RecruitSpider/RecruitSpider/items.py:277:get_zhilian_position_insert_sql
/Users/monstar/Envs/Spider/lib/python3.6/site-packages/scrapy/item.py:59:__getitem__
]2017-10-16 18:06:45
[Failure instance: Traceback: <class 'KeyError'>: 'advantage_labels'
/usr/local/Cellar/python3/3.6.1/Frameworks/Python.framework/Versions/3.6/lib/python3.6/threading.py:916:_bootstrap_inner
/usr/local/Cellar/python3/3.6.1/Frameworks/Python.framework/Versions/3.6/lib/python3.6/threading.py:864:run
/Users/monstar/Envs/Spider/lib/python3.6/site-packages/twisted/_threads/_threadworker.py:46:work
/Users/monstar/Envs/Spider/lib/python3.6/site-packages/twisted/_threads/_team.py:190:doWork
--- <exception caught here> ---
/Users/monstar/Envs/Spider/lib/python3.6/site-packages/twisted/python/threadpool.py:250:inContext
/Users/monstar/Envs/Spider/lib/python3.6/site-packages/twisted/python/threadpool.py:266:<lambda>
/Users/monstar/Envs/Spider/lib/python3.6/site-packages/twisted/python/context.py:122:callWithContext
/Users/monstar/Envs/Spider/lib/python3.6/site-packages/twisted/python/context.py:85:callWithContext
/Users/monstar/Envs/Spider/lib/python3.6/site-packages/twisted/enterprise/adbapi.py:477:_runInteraction
/Users/monstar/Envs/Spider/lib/python3.6/site-packages/twisted/python/compat.py:477:reraise
/Users/monstar/Envs/Spider/lib/python3.6/site-packages/twisted/enterprise/adbapi.py:467:_runInteraction
/Users/monstar/Desktop/ProjectCode/bigdatarecruit/SpiderMan/RecruitSpider/RecruitSpider/pipelines.py:108:do_insert_position
/Users/monstar/Desktop/ProjectCode/bigdatarecruit/SpiderMan/RecruitSpider/RecruitSpider/items.py:277:get_zhilian_position_insert_sql
/Users/monstar/Envs/Spider/lib/python3.6/site-packages/scrapy/item.py:59:__getitem__
]2017-10-16 18:06:53
[Failure instance: Traceback: <class 'KeyError'>: 'industry'
/usr/local/Cellar/python3/3.6.1/Frameworks/Python.framework/Versions/3.6/lib/python3.6/threading.py:916:_bootstrap_inner
/usr/local/Cellar/python3/3.6.1/Frameworks/Python.framework/Versions/3.6/lib/python3.6/threading.py:864:run
/Users/monstar/Envs/Spider/lib/python3.6/site-packages/twisted/_threads/_threadworker.py:46:work
/Users/monstar/Envs/Spider/lib/python3.6/site-packages/twisted/_threads/_team.py:190:doWork
--- <exception caught here> ---
/Users/monstar/Envs/Spider/lib/python3.6/site-packages/twisted/python/threadpool.py:250:inContext
/Users/monstar/Envs/Spider/lib/python3.6/site-packages/twisted/python/threadpool.py:266:<lambda>
/Users/monstar/Envs/Spider/lib/python3.6/site-packages/twisted/python/context.py:122:callWithContext
/Users/monstar/Envs/Spider/lib/python3.6/site-packages/twisted/python/context.py:85:callWithContext
/Users/monstar/Envs/Spider/lib/python3.6/site-packages/twisted/enterprise/adbapi.py:477:_runInteraction
/Users/monstar/Envs/Spider/lib/python3.6/site-packages/twisted/python/compat.py:477:reraise
/Users/monstar/Envs/Spider/lib/python3.6/site-packages/twisted/enterprise/adbapi.py:467:_runInteraction
/Users/monstar/Desktop/ProjectCode/bigdatarecruit/SpiderMan/RecruitSpider/RecruitSpider/pipelines.py:104:do_insert_company
/Users/monstar/Desktop/ProjectCode/bigdatarecruit/SpiderMan/RecruitSpider/RecruitSpider/items.py:250:get_zhilian_company_insert_sql
/Users/monstar/Envs/Spider/lib/python3.6/site-packages/scrapy/item.py:59:__getitem__
]2017-10-16 18:06:54
[Failure instance: Traceback: <class 'KeyError'>: 'advantage_labels'
/usr/local/Cellar/python3/3.6.1/Frameworks/Python.framework/Versions/3.6/lib/python3.6/threading.py:916:_bootstrap_inner
/usr/local/Cellar/python3/3.6.1/Frameworks/Python.framework/Versions/3.6/lib/python3.6/threading.py:864:run
/Users/monstar/Envs/Spider/lib/python3.6/site-packages/twisted/_threads/_threadworker.py:46:work
/Users/monstar/Envs/Spider/lib/python3.6/site-packages/twisted/_threads/_team.py:190:doWork
--- <exception caught here> ---
/Users/monstar/Envs/Spider/lib/python3.6/site-packages/twisted/python/threadpool.py:250:inContext
/Users/monstar/Envs/Spider/lib/python3.6/site-packages/twisted/python/threadpool.py:266:<lambda>
/Users/monstar/Envs/Spider/lib/python3.6/site-packages/twisted/python/context.py:122:callWithContext
/Users/monstar/Envs/Spider/lib/python3.6/site-packages/twisted/python/context.py:85:callWithContext
/Users/monstar/Envs/Spider/lib/python3.6/site-packages/twisted/enterprise/adbapi.py:477:_runInteraction
/Users/monstar/Envs/Spider/lib/python3.6/site-packages/twisted/python/compat.py:477:reraise
/Users/monstar/Envs/Spider/lib/python3.6/site-packages/twisted/enterprise/adbapi.py:467:_runInteraction
/Users/monstar/Desktop/ProjectCode/bigdatarecruit/SpiderMan/RecruitSpider/RecruitSpider/pipelines.py:108:do_insert_position
/Users/monstar/Desktop/ProjectCode/bigdatarecruit/SpiderMan/RecruitSpider/RecruitSpider/items.py:277:get_zhilian_position_insert_sql
/Users/monstar/Envs/Spider/lib/python3.6/site-packages/scrapy/item.py:59:__getitem__
]2017-10-16 18:06:54
[Failure instance: Traceback: <class 'KeyError'>: 'industry'
/usr/local/Cellar/python3/3.6.1/Frameworks/Python.framework/Versions/3.6/lib/python3.6/threading.py:916:_bootstrap_inner
/usr/local/Cellar/python3/3.6.1/Frameworks/Python.framework/Versions/3.6/lib/python3.6/threading.py:864:run
/Users/monstar/Envs/Spider/lib/python3.6/site-packages/twisted/_threads/_threadworker.py:46:work
/Users/monstar/Envs/Spider/lib/python3.6/site-packages/twisted/_threads/_team.py:190:doWork
--- <exception caught here> ---
/Users/monstar/Envs/Spider/lib/python3.6/site-packages/twisted/python/threadpool.py:250:inContext
/Users/monstar/Envs/Spider/lib/python3.6/site-packages/twisted/python/threadpool.py:266:<lambda>
/Users/monstar/Envs/Spider/lib/python3.6/site-packages/twisted/python/context.py:122:callWithContext
/Users/monstar/Envs/Spider/lib/python3.6/site-packages/twisted/python/context.py:85:callWithContext
/Users/monstar/Envs/Spider/lib/python3.6/site-packages/twisted/enterprise/adbapi.py:477:_runInteraction
/Users/monstar/Envs/Spider/lib/python3.6/site-packages/twisted/python/compat.py:477:reraise
/Users/monstar/Envs/Spider/lib/python3.6/site-packages/twisted/enterprise/adbapi.py:467:_runInteraction
/Users/monstar/Desktop/ProjectCode/bigdatarecruit/SpiderMan/RecruitSpider/RecruitSpider/pipelines.py:104:do_insert_company
/Users/monstar/Desktop/ProjectCode/bigdatarecruit/SpiderMan/RecruitSpider/RecruitSpider/items.py:250:get_zhilian_company_insert_sql
/Users/monstar/Envs/Spider/lib/python3.6/site-packages/scrapy/item.py:59:__getitem__
]2017-10-16 18:06:55
[Failure instance: Traceback: <class 'KeyError'>: 'content'
/usr/local/Cellar/python3/3.6.1/Frameworks/Python.framework/Versions/3.6/lib/python3.6/threading.py:916:_bootstrap_inner
/usr/local/Cellar/python3/3.6.1/Frameworks/Python.framework/Versions/3.6/lib/python3.6/threading.py:864:run
/Users/monstar/Envs/Spider/lib/python3.6/site-packages/twisted/_threads/_threadworker.py:46:work
/Users/monstar/Envs/Spider/lib/python3.6/site-packages/twisted/_threads/_team.py:190:doWork
--- <exception caught here> ---
/Users/monstar/Envs/Spider/lib/python3.6/site-packages/twisted/python/threadpool.py:250:inContext
/Users/monstar/Envs/Spider/lib/python3.6/site-packages/twisted/python/threadpool.py:266:<lambda>
/Users/monstar/Envs/Spider/lib/python3.6/site-packages/twisted/python/context.py:122:callWithContext
/Users/monstar/Envs/Spider/lib/python3.6/site-packages/twisted/python/context.py:85:callWithContext
/Users/monstar/Envs/Spider/lib/python3.6/site-packages/twisted/enterprise/adbapi.py:477:_runInteraction
/Users/monstar/Envs/Spider/lib/python3.6/site-packages/twisted/python/compat.py:477:reraise
/Users/monstar/Envs/Spider/lib/python3.6/site-packages/twisted/enterprise/adbapi.py:467:_runInteraction
/Users/monstar/Desktop/ProjectCode/bigdatarecruit/SpiderMan/RecruitSpider/RecruitSpider/pipelines.py:108:do_insert_position
/Users/monstar/Desktop/ProjectCode/bigdatarecruit/SpiderMan/RecruitSpider/RecruitSpider/items.py:277:get_zhilian_position_insert_sql
/Users/monstar/Envs/Spider/lib/python3.6/site-packages/scrapy/item.py:59:__getitem__
]2017-10-16 18:06:55
[Failure instance: Traceback: <class 'KeyError'>: 'industry'
/usr/local/Cellar/python3/3.6.1/Frameworks/Python.framework/Versions/3.6/lib/python3.6/threading.py:916:_bootstrap_inner
/usr/local/Cellar/python3/3.6.1/Frameworks/Python.framework/Versions/3.6/lib/python3.6/threading.py:864:run
/Users/monstar/Envs/Spider/lib/python3.6/site-packages/twisted/_threads/_threadworker.py:46:work
/Users/monstar/Envs/Spider/lib/python3.6/site-packages/twisted/_threads/_team.py:190:doWork
--- <exception caught here> ---
/Users/monstar/Envs/Spider/lib/python3.6/site-packages/twisted/python/threadpool.py:250:inContext
/Users/monstar/Envs/Spider/lib/python3.6/site-packages/twisted/python/threadpool.py:266:<lambda>
/Users/monstar/Envs/Spider/lib/python3.6/site-packages/twisted/python/context.py:122:callWithContext
/Users/monstar/Envs/Spider/lib/python3.6/site-packages/twisted/python/context.py:85:callWithContext
/Users/monstar/Envs/Spider/lib/python3.6/site-packages/twisted/enterprise/adbapi.py:477:_runInteraction
/Users/monstar/Envs/Spider/lib/python3.6/site-packages/twisted/python/compat.py:477:reraise
/Users/monstar/Envs/Spider/lib/python3.6/site-packages/twisted/enterprise/adbapi.py:467:_runInteraction
/Users/monstar/Desktop/ProjectCode/bigdatarecruit/SpiderMan/RecruitSpider/RecruitSpider/pipelines.py:104:do_insert_company
/Users/monstar/Desktop/ProjectCode/bigdatarecruit/SpiderMan/RecruitSpider/RecruitSpider/items.py:250:get_zhilian_company_insert_sql
/Users/monstar/Envs/Spider/lib/python3.6/site-packages/scrapy/item.py:59:__getitem__
]2017-10-16 18:06:58
[Failure instance: Traceback: <class 'KeyError'>: 'industry'
/usr/local/Cellar/python3/3.6.1/Frameworks/Python.framework/Versions/3.6/lib/python3.6/threading.py:916:_bootstrap_inner
/usr/local/Cellar/python3/3.6.1/Frameworks/Python.framework/Versions/3.6/lib/python3.6/threading.py:864:run
/Users/monstar/Envs/Spider/lib/python3.6/site-packages/twisted/_threads/_threadworker.py:46:work
/Users/monstar/Envs/Spider/lib/python3.6/site-packages/twisted/_threads/_team.py:190:doWork
--- <exception caught here> ---
/Users/monstar/Envs/Spider/lib/python3.6/site-packages/twisted/python/threadpool.py:250:inContext
/Users/monstar/Envs/Spider/lib/python3.6/site-packages/twisted/python/threadpool.py:266:<lambda>
/Users/monstar/Envs/Spider/lib/python3.6/site-packages/twisted/python/context.py:122:callWithContext
/Users/monstar/Envs/Spider/lib/python3.6/site-packages/twisted/python/context.py:85:callWithContext
/Users/monstar/Envs/Spider/lib/python3.6/site-packages/twisted/enterprise/adbapi.py:477:_runInteraction
/Users/monstar/Envs/Spider/lib/python3.6/site-packages/twisted/python/compat.py:477:reraise
/Users/monstar/Envs/Spider/lib/python3.6/site-packages/twisted/enterprise/adbapi.py:467:_runInteraction
/Users/monstar/Desktop/ProjectCode/bigdatarecruit/SpiderMan/RecruitSpider/RecruitSpider/pipelines.py:104:do_insert_company
/Users/monstar/Desktop/ProjectCode/bigdatarecruit/SpiderMan/RecruitSpider/RecruitSpider/items.py:250:get_zhilian_company_insert_sql
/Users/monstar/Envs/Spider/lib/python3.6/site-packages/scrapy/item.py:59:__getitem__
]2017-10-16 18:07:03
[Failure instance: Traceback: <class 'KeyError'>: 'industry'
/usr/local/Cellar/python3/3.6.1/Frameworks/Python.framework/Versions/3.6/lib/python3.6/threading.py:916:_bootstrap_inner
/usr/local/Cellar/python3/3.6.1/Frameworks/Python.framework/Versions/3.6/lib/python3.6/threading.py:864:run
/Users/monstar/Envs/Spider/lib/python3.6/site-packages/twisted/_threads/_threadworker.py:46:work
/Users/monstar/Envs/Spider/lib/python3.6/site-packages/twisted/_threads/_team.py:190:doWork
--- <exception caught here> ---
/Users/monstar/Envs/Spider/lib/python3.6/site-packages/twisted/python/threadpool.py:250:inContext
/Users/monstar/Envs/Spider/lib/python3.6/site-packages/twisted/python/threadpool.py:266:<lambda>
/Users/monstar/Envs/Spider/lib/python3.6/site-packages/twisted/python/context.py:122:callWithContext
/Users/monstar/Envs/Spider/lib/python3.6/site-packages/twisted/python/context.py:85:callWithContext
/Users/monstar/Envs/Spider/lib/python3.6/site-packages/twisted/enterprise/adbapi.py:477:_runInteraction
/Users/monstar/Envs/Spider/lib/python3.6/site-packages/twisted/python/compat.py:477:reraise
/Users/monstar/Envs/Spider/lib/python3.6/site-packages/twisted/enterprise/adbapi.py:467:_runInteraction
/Users/monstar/Desktop/ProjectCode/bigdatarecruit/SpiderMan/RecruitSpider/RecruitSpider/pipelines.py:104:do_insert_company
/Users/monstar/Desktop/ProjectCode/bigdatarecruit/SpiderMan/RecruitSpider/RecruitSpider/items.py:250:get_zhilian_company_insert_sql
/Users/monstar/Envs/Spider/lib/python3.6/site-packages/scrapy/item.py:59:__getitem__
]2017-10-16 18:07:05
[Failure instance: Traceback: <class 'KeyError'>: 'industry'
/usr/local/Cellar/python3/3.6.1/Frameworks/Python.framework/Versions/3.6/lib/python3.6/threading.py:916:_bootstrap_inner
/usr/local/Cellar/python3/3.6.1/Frameworks/Python.framework/Versions/3.6/lib/python3.6/threading.py:864:run
/Users/monstar/Envs/Spider/lib/python3.6/site-packages/twisted/_threads/_threadworker.py:46:work
/Users/monstar/Envs/Spider/lib/python3.6/site-packages/twisted/_threads/_team.py:190:doWork
--- <exception caught here> ---
/Users/monstar/Envs/Spider/lib/python3.6/site-packages/twisted/python/threadpool.py:250:inContext
/Users/monstar/Envs/Spider/lib/python3.6/site-packages/twisted/python/threadpool.py:266:<lambda>
/Users/monstar/Envs/Spider/lib/python3.6/site-packages/twisted/python/context.py:122:callWithContext
/Users/monstar/Envs/Spider/lib/python3.6/site-packages/twisted/python/context.py:85:callWithContext
/Users/monstar/Envs/Spider/lib/python3.6/site-packages/twisted/enterprise/adbapi.py:477:_runInteraction
/Users/monstar/Envs/Spider/lib/python3.6/site-packages/twisted/python/compat.py:477:reraise
/Users/monstar/Envs/Spider/lib/python3.6/site-packages/twisted/enterprise/adbapi.py:467:_runInteraction
/Users/monstar/Desktop/ProjectCode/bigdatarecruit/SpiderMan/RecruitSpider/RecruitSpider/pipelines.py:104:do_insert_company
/Users/monstar/Desktop/ProjectCode/bigdatarecruit/SpiderMan/RecruitSpider/RecruitSpider/items.py:250:get_zhilian_company_insert_sql
/Users/monstar/Envs/Spider/lib/python3.6/site-packages/scrapy/item.py:59:__getitem__
]2017-10-16 18:07:05
[Failure instance: Traceback: <class 'KeyError'>: 'content'
/usr/local/Cellar/python3/3.6.1/Frameworks/Python.framework/Versions/3.6/lib/python3.6/threading.py:916:_bootstrap_inner
/usr/local/Cellar/python3/3.6.1/Frameworks/Python.framework/Versions/3.6/lib/python3.6/threading.py:864:run
/Users/monstar/Envs/Spider/lib/python3.6/site-packages/twisted/_threads/_threadworker.py:46:work
/Users/monstar/Envs/Spider/lib/python3.6/site-packages/twisted/_threads/_team.py:190:doWork
--- <exception caught here> ---
/Users/monstar/Envs/Spider/lib/python3.6/site-packages/twisted/python/threadpool.py:250:inContext
/Users/monstar/Envs/Spider/lib/python3.6/site-packages/twisted/python/threadpool.py:266:<lambda>
/Users/monstar/Envs/Spider/lib/python3.6/site-packages/twisted/python/context.py:122:callWithContext
/Users/monstar/Envs/Spider/lib/python3.6/site-packages/twisted/python/context.py:85:callWithContext
/Users/monstar/Envs/Spider/lib/python3.6/site-packages/twisted/enterprise/adbapi.py:477:_runInteraction
/Users/monstar/Envs/Spider/lib/python3.6/site-packages/twisted/python/compat.py:477:reraise
/Users/monstar/Envs/Spider/lib/python3.6/site-packages/twisted/enterprise/adbapi.py:467:_runInteraction
/Users/monstar/Desktop/ProjectCode/bigdatarecruit/SpiderMan/RecruitSpider/RecruitSpider/pipelines.py:108:do_insert_position
/Users/monstar/Desktop/ProjectCode/bigdatarecruit/SpiderMan/RecruitSpider/RecruitSpider/items.py:277:get_zhilian_position_insert_sql
/Users/monstar/Envs/Spider/lib/python3.6/site-packages/scrapy/item.py:59:__getitem__
]2017-10-16 18:07:06
[Failure instance: Traceback: <class 'KeyError'>: 'advantage_labels'
/usr/local/Cellar/python3/3.6.1/Frameworks/Python.framework/Versions/3.6/lib/python3.6/threading.py:916:_bootstrap_inner
/usr/local/Cellar/python3/3.6.1/Frameworks/Python.framework/Versions/3.6/lib/python3.6/threading.py:864:run
/Users/monstar/Envs/Spider/lib/python3.6/site-packages/twisted/_threads/_threadworker.py:46:work
/Users/monstar/Envs/Spider/lib/python3.6/site-packages/twisted/_threads/_team.py:190:doWork
--- <exception caught here> ---
/Users/monstar/Envs/Spider/lib/python3.6/site-packages/twisted/python/threadpool.py:250:inContext
/Users/monstar/Envs/Spider/lib/python3.6/site-packages/twisted/python/threadpool.py:266:<lambda>
/Users/monstar/Envs/Spider/lib/python3.6/site-packages/twisted/python/context.py:122:callWithContext
/Users/monstar/Envs/Spider/lib/python3.6/site-packages/twisted/python/context.py:85:callWithContext
/Users/monstar/Envs/Spider/lib/python3.6/site-packages/twisted/enterprise/adbapi.py:477:_runInteraction
/Users/monstar/Envs/Spider/lib/python3.6/site-packages/twisted/python/compat.py:477:reraise
/Users/monstar/Envs/Spider/lib/python3.6/site-packages/twisted/enterprise/adbapi.py:467:_runInteraction
/Users/monstar/Desktop/ProjectCode/bigdatarecruit/SpiderMan/RecruitSpider/RecruitSpider/pipelines.py:108:do_insert_position
/Users/monstar/Desktop/ProjectCode/bigdatarecruit/SpiderMan/RecruitSpider/RecruitSpider/items.py:277:get_zhilian_position_insert_sql
/Users/monstar/Envs/Spider/lib/python3.6/site-packages/scrapy/item.py:59:__getitem__
]2017-10-16 18:42:33
[Failure instance: Traceback: <class 'KeyError'>: 'salary_low'
/usr/local/Cellar/python3/3.6.1/Frameworks/Python.framework/Versions/3.6/lib/python3.6/threading.py:916:_bootstrap_inner
/usr/local/Cellar/python3/3.6.1/Frameworks/Python.framework/Versions/3.6/lib/python3.6/threading.py:864:run
/Users/monstar/Envs/Spider/lib/python3.6/site-packages/twisted/_threads/_threadworker.py:46:work
/Users/monstar/Envs/Spider/lib/python3.6/site-packages/twisted/_threads/_team.py:190:doWork
--- <exception caught here> ---
/Users/monstar/Envs/Spider/lib/python3.6/site-packages/twisted/python/threadpool.py:250:inContext
/Users/monstar/Envs/Spider/lib/python3.6/site-packages/twisted/python/threadpool.py:266:<lambda>
/Users/monstar/Envs/Spider/lib/python3.6/site-packages/twisted/python/context.py:122:callWithContext
/Users/monstar/Envs/Spider/lib/python3.6/site-packages/twisted/python/context.py:85:callWithContext
/Users/monstar/Envs/Spider/lib/python3.6/site-packages/twisted/enterprise/adbapi.py:477:_runInteraction
/Users/monstar/Envs/Spider/lib/python3.6/site-packages/twisted/python/compat.py:477:reraise
/Users/monstar/Envs/Spider/lib/python3.6/site-packages/twisted/enterprise/adbapi.py:467:_runInteraction
/Users/monstar/Desktop/ProjectCode/bigdatarecruit/SpiderMan/RecruitSpider/RecruitSpider/pipelines.py:108:do_insert_position
/Users/monstar/Desktop/ProjectCode/bigdatarecruit/SpiderMan/RecruitSpider/RecruitSpider/items.py:277:get_zhilian_position_insert_sql
/Users/monstar/Envs/Spider/lib/python3.6/site-packages/scrapy/item.py:59:__getitem__
]2017-10-16 18:42:39
[Failure instance: Traceback: <class 'KeyError'>: 'website'
/usr/local/Cellar/python3/3.6.1/Frameworks/Python.framework/Versions/3.6/lib/python3.6/threading.py:916:_bootstrap_inner
/usr/local/Cellar/python3/3.6.1/Frameworks/Python.framework/Versions/3.6/lib/python3.6/threading.py:864:run
/Users/monstar/Envs/Spider/lib/python3.6/site-packages/twisted/_threads/_threadworker.py:46:work
/Users/monstar/Envs/Spider/lib/python3.6/site-packages/twisted/_threads/_team.py:190:doWork
--- <exception caught here> ---
/Users/monstar/Envs/Spider/lib/python3.6/site-packages/twisted/python/threadpool.py:250:inContext
/Users/monstar/Envs/Spider/lib/python3.6/site-packages/twisted/python/threadpool.py:266:<lambda>
/Users/monstar/Envs/Spider/lib/python3.6/site-packages/twisted/python/context.py:122:callWithContext
/Users/monstar/Envs/Spider/lib/python3.6/site-packages/twisted/python/context.py:85:callWithContext
/Users/monstar/Envs/Spider/lib/python3.6/site-packages/twisted/enterprise/adbapi.py:477:_runInteraction
/Users/monstar/Envs/Spider/lib/python3.6/site-packages/twisted/python/compat.py:477:reraise
/Users/monstar/Envs/Spider/lib/python3.6/site-packages/twisted/enterprise/adbapi.py:467:_runInteraction
/Users/monstar/Desktop/ProjectCode/bigdatarecruit/SpiderMan/RecruitSpider/RecruitSpider/pipelines.py:104:do_insert_company
/Users/monstar/Desktop/ProjectCode/bigdatarecruit/SpiderMan/RecruitSpider/RecruitSpider/items.py:250:get_zhilian_company_insert_sql
/Users/monstar/Envs/Spider/lib/python3.6/site-packages/scrapy/item.py:59:__getitem__
]2017-10-16 18:42:41
[Failure instance: Traceback: <class 'KeyError'>: 'website'
/usr/local/Cellar/python3/3.6.1/Frameworks/Python.framework/Versions/3.6/lib/python3.6/threading.py:916:_bootstrap_inner
/usr/local/Cellar/python3/3.6.1/Frameworks/Python.framework/Versions/3.6/lib/python3.6/threading.py:864:run
/Users/monstar/Envs/Spider/lib/python3.6/site-packages/twisted/_threads/_threadworker.py:46:work
/Users/monstar/Envs/Spider/lib/python3.6/site-packages/twisted/_threads/_team.py:190:doWork
--- <exception caught here> ---
/Users/monstar/Envs/Spider/lib/python3.6/site-packages/twisted/python/threadpool.py:250:inContext
/Users/monstar/Envs/Spider/lib/python3.6/site-packages/twisted/python/threadpool.py:266:<lambda>
/Users/monstar/Envs/Spider/lib/python3.6/site-packages/twisted/python/context.py:122:callWithContext
/Users/monstar/Envs/Spider/lib/python3.6/site-packages/twisted/python/context.py:85:callWithContext
/Users/monstar/Envs/Spider/lib/python3.6/site-packages/twisted/enterprise/adbapi.py:477:_runInteraction
/Users/monstar/Envs/Spider/lib/python3.6/site-packages/twisted/python/compat.py:477:reraise
/Users/monstar/Envs/Spider/lib/python3.6/site-packages/twisted/enterprise/adbapi.py:467:_runInteraction
/Users/monstar/Desktop/ProjectCode/bigdatarecruit/SpiderMan/RecruitSpider/RecruitSpider/pipelines.py:104:do_insert_company
/Users/monstar/Desktop/ProjectCode/bigdatarecruit/SpiderMan/RecruitSpider/RecruitSpider/items.py:250:get_zhilian_company_insert_sql
/Users/monstar/Envs/Spider/lib/python3.6/site-packages/scrapy/item.py:59:__getitem__
]2017-10-16 18:42:42
[Failure instance: Traceback: <class 'KeyError'>: 'content'
/usr/local/Cellar/python3/3.6.1/Frameworks/Python.framework/Versions/3.6/lib/python3.6/threading.py:916:_bootstrap_inner
/usr/local/Cellar/python3/3.6.1/Frameworks/Python.framework/Versions/3.6/lib/python3.6/threading.py:864:run
/Users/monstar/Envs/Spider/lib/python3.6/site-packages/twisted/_threads/_threadworker.py:46:work
/Users/monstar/Envs/Spider/lib/python3.6/site-packages/twisted/_threads/_team.py:190:doWork
--- <exception caught here> ---
/Users/monstar/Envs/Spider/lib/python3.6/site-packages/twisted/python/threadpool.py:250:inContext
/Users/monstar/Envs/Spider/lib/python3.6/site-packages/twisted/python/threadpool.py:266:<lambda>
/Users/monstar/Envs/Spider/lib/python3.6/site-packages/twisted/python/context.py:122:callWithContext
/Users/monstar/Envs/Spider/lib/python3.6/site-packages/twisted/python/context.py:85:callWithContext
/Users/monstar/Envs/Spider/lib/python3.6/site-packages/twisted/enterprise/adbapi.py:477:_runInteraction
/Users/monstar/Envs/Spider/lib/python3.6/site-packages/twisted/python/compat.py:477:reraise
/Users/monstar/Envs/Spider/lib/python3.6/site-packages/twisted/enterprise/adbapi.py:467:_runInteraction
/Users/monstar/Desktop/ProjectCode/bigdatarecruit/SpiderMan/RecruitSpider/RecruitSpider/pipelines.py:108:do_insert_position
/Users/monstar/Desktop/ProjectCode/bigdatarecruit/SpiderMan/RecruitSpider/RecruitSpider/items.py:277:get_zhilian_position_insert_sql
/Users/monstar/Envs/Spider/lib/python3.6/site-packages/scrapy/item.py:59:__getitem__
]2017-10-16 18:42:42
[Failure instance: Traceback: <class 'KeyError'>: 'website'
/usr/local/Cellar/python3/3.6.1/Frameworks/Python.framework/Versions/3.6/lib/python3.6/threading.py:916:_bootstrap_inner
/usr/local/Cellar/python3/3.6.1/Frameworks/Python.framework/Versions/3.6/lib/python3.6/threading.py:864:run
/Users/monstar/Envs/Spider/lib/python3.6/site-packages/twisted/_threads/_threadworker.py:46:work
/Users/monstar/Envs/Spider/lib/python3.6/site-packages/twisted/_threads/_team.py:190:doWork
--- <exception caught here> ---
/Users/monstar/Envs/Spider/lib/python3.6/site-packages/twisted/python/threadpool.py:250:inContext
/Users/monstar/Envs/Spider/lib/python3.6/site-packages/twisted/python/threadpool.py:266:<lambda>
/Users/monstar/Envs/Spider/lib/python3.6/site-packages/twisted/python/context.py:122:callWithContext
/Users/monstar/Envs/Spider/lib/python3.6/site-packages/twisted/python/context.py:85:callWithContext
/Users/monstar/Envs/Spider/lib/python3.6/site-packages/twisted/enterprise/adbapi.py:477:_runInteraction
/Users/monstar/Envs/Spider/lib/python3.6/site-packages/twisted/python/compat.py:477:reraise
/Users/monstar/Envs/Spider/lib/python3.6/site-packages/twisted/enterprise/adbapi.py:467:_runInteraction
/Users/monstar/Desktop/ProjectCode/bigdatarecruit/SpiderMan/RecruitSpider/RecruitSpider/pipelines.py:104:do_insert_company
/Users/monstar/Desktop/ProjectCode/bigdatarecruit/SpiderMan/RecruitSpider/RecruitSpider/items.py:250:get_zhilian_company_insert_sql
/Users/monstar/Envs/Spider/lib/python3.6/site-packages/scrapy/item.py:59:__getitem__
]2017-10-16 18:53:54
[Failure instance: Traceback: <class 'KeyError'>: 'content'
/usr/local/Cellar/python3/3.6.1/Frameworks/Python.framework/Versions/3.6/lib/python3.6/threading.py:916:_bootstrap_inner
/usr/local/Cellar/python3/3.6.1/Frameworks/Python.framework/Versions/3.6/lib/python3.6/threading.py:864:run
/Users/monstar/Envs/Spider/lib/python3.6/site-packages/twisted/_threads/_threadworker.py:46:work
/Users/monstar/Envs/Spider/lib/python3.6/site-packages/twisted/_threads/_team.py:190:doWork
--- <exception caught here> ---
/Users/monstar/Envs/Spider/lib/python3.6/site-packages/twisted/python/threadpool.py:250:inContext
/Users/monstar/Envs/Spider/lib/python3.6/site-packages/twisted/python/threadpool.py:266:<lambda>
/Users/monstar/Envs/Spider/lib/python3.6/site-packages/twisted/python/context.py:122:callWithContext
/Users/monstar/Envs/Spider/lib/python3.6/site-packages/twisted/python/context.py:85:callWithContext
/Users/monstar/Envs/Spider/lib/python3.6/site-packages/twisted/enterprise/adbapi.py:477:_runInteraction
/Users/monstar/Envs/Spider/lib/python3.6/site-packages/twisted/python/compat.py:477:reraise
/Users/monstar/Envs/Spider/lib/python3.6/site-packages/twisted/enterprise/adbapi.py:467:_runInteraction
/Users/monstar/Desktop/ProjectCode/bigdatarecruit/SpiderMan/RecruitSpider/RecruitSpider/pipelines.py:108:do_insert_position
/Users/monstar/Desktop/ProjectCode/bigdatarecruit/SpiderMan/RecruitSpider/RecruitSpider/items.py:281:get_zhilian_position_insert_sql
/Users/monstar/Envs/Spider/lib/python3.6/site-packages/scrapy/item.py:59:__getitem__
]2017-10-16 18:53:57
[Failure instance: Traceback: <class 'KeyError'>: 'industry'
/usr/local/Cellar/python3/3.6.1/Frameworks/Python.framework/Versions/3.6/lib/python3.6/threading.py:916:_bootstrap_inner
/usr/local/Cellar/python3/3.6.1/Frameworks/Python.framework/Versions/3.6/lib/python3.6/threading.py:864:run
/Users/monstar/Envs/Spider/lib/python3.6/site-packages/twisted/_threads/_threadworker.py:46:work
/Users/monstar/Envs/Spider/lib/python3.6/site-packages/twisted/_threads/_team.py:190:doWork
--- <exception caught here> ---
/Users/monstar/Envs/Spider/lib/python3.6/site-packages/twisted/python/threadpool.py:250:inContext
/Users/monstar/Envs/Spider/lib/python3.6/site-packages/twisted/python/threadpool.py:266:<lambda>
/Users/monstar/Envs/Spider/lib/python3.6/site-packages/twisted/python/context.py:122:callWithContext
/Users/monstar/Envs/Spider/lib/python3.6/site-packages/twisted/python/context.py:85:callWithContext
/Users/monstar/Envs/Spider/lib/python3.6/site-packages/twisted/enterprise/adbapi.py:477:_runInteraction
/Users/monstar/Envs/Spider/lib/python3.6/site-packages/twisted/python/compat.py:477:reraise
/Users/monstar/Envs/Spider/lib/python3.6/site-packages/twisted/enterprise/adbapi.py:467:_runInteraction
/Users/monstar/Desktop/ProjectCode/bigdatarecruit/SpiderMan/RecruitSpider/RecruitSpider/pipelines.py:104:do_insert_company
/Users/monstar/Desktop/ProjectCode/bigdatarecruit/SpiderMan/RecruitSpider/RecruitSpider/items.py:254:get_zhilian_company_insert_sql
/Users/monstar/Envs/Spider/lib/python3.6/site-packages/scrapy/item.py:59:__getitem__
]2017-10-16 18:54:26
[Failure instance: Traceback: <class 'KeyError'>: 'content'
/usr/local/Cellar/python3/3.6.1/Frameworks/Python.framework/Versions/3.6/lib/python3.6/threading.py:916:_bootstrap_inner
/usr/local/Cellar/python3/3.6.1/Frameworks/Python.framework/Versions/3.6/lib/python3.6/threading.py:864:run
/Users/monstar/Envs/Spider/lib/python3.6/site-packages/twisted/_threads/_threadworker.py:46:work
/Users/monstar/Envs/Spider/lib/python3.6/site-packages/twisted/_threads/_team.py:190:doWork
--- <exception caught here> ---
/Users/monstar/Envs/Spider/lib/python3.6/site-packages/twisted/python/threadpool.py:250:inContext
/Users/monstar/Envs/Spider/lib/python3.6/site-packages/twisted/python/threadpool.py:266:<lambda>
/Users/monstar/Envs/Spider/lib/python3.6/site-packages/twisted/python/context.py:122:callWithContext
/Users/monstar/Envs/Spider/lib/python3.6/site-packages/twisted/python/context.py:85:callWithContext
/Users/monstar/Envs/Spider/lib/python3.6/site-packages/twisted/enterprise/adbapi.py:477:_runInteraction
/Users/monstar/Envs/Spider/lib/python3.6/site-packages/twisted/python/compat.py:477:reraise
/Users/monstar/Envs/Spider/lib/python3.6/site-packages/twisted/enterprise/adbapi.py:467:_runInteraction
/Users/monstar/Desktop/ProjectCode/bigdatarecruit/SpiderMan/RecruitSpider/RecruitSpider/pipelines.py:108:do_insert_position
/Users/monstar/Desktop/ProjectCode/bigdatarecruit/SpiderMan/RecruitSpider/RecruitSpider/items.py:281:get_zhilian_position_insert_sql
/Users/monstar/Envs/Spider/lib/python3.6/site-packages/scrapy/item.py:59:__getitem__
]2017-10-16 18:55:03
[Failure instance: Traceback: <class 'KeyError'>: 'address'
/usr/local/Cellar/python3/3.6.1/Frameworks/Python.framework/Versions/3.6/lib/python3.6/threading.py:916:_bootstrap_inner
/usr/local/Cellar/python3/3.6.1/Frameworks/Python.framework/Versions/3.6/lib/python3.6/threading.py:864:run
/Users/monstar/Envs/Spider/lib/python3.6/site-packages/twisted/_threads/_threadworker.py:46:work
/Users/monstar/Envs/Spider/lib/python3.6/site-packages/twisted/_threads/_team.py:190:doWork
--- <exception caught here> ---
/Users/monstar/Envs/Spider/lib/python3.6/site-packages/twisted/python/threadpool.py:250:inContext
/Users/monstar/Envs/Spider/lib/python3.6/site-packages/twisted/python/threadpool.py:266:<lambda>
/Users/monstar/Envs/Spider/lib/python3.6/site-packages/twisted/python/context.py:122:callWithContext
/Users/monstar/Envs/Spider/lib/python3.6/site-packages/twisted/python/context.py:85:callWithContext
/Users/monstar/Envs/Spider/lib/python3.6/site-packages/twisted/enterprise/adbapi.py:477:_runInteraction
/Users/monstar/Envs/Spider/lib/python3.6/site-packages/twisted/python/compat.py:477:reraise
/Users/monstar/Envs/Spider/lib/python3.6/site-packages/twisted/enterprise/adbapi.py:467:_runInteraction
/Users/monstar/Desktop/ProjectCode/bigdatarecruit/SpiderMan/RecruitSpider/RecruitSpider/pipelines.py:104:do_insert_company
/Users/monstar/Desktop/ProjectCode/bigdatarecruit/SpiderMan/RecruitSpider/RecruitSpider/items.py:254:get_zhilian_company_insert_sql
/Users/monstar/Envs/Spider/lib/python3.6/site-packages/scrapy/item.py:59:__getitem__
]2017-10-16 18:55:19
[Failure instance: Traceback: <class 'KeyError'>: 'address'
/usr/local/Cellar/python3/3.6.1/Frameworks/Python.framework/Versions/3.6/lib/python3.6/threading.py:916:_bootstrap_inner
/usr/local/Cellar/python3/3.6.1/Frameworks/Python.framework/Versions/3.6/lib/python3.6/threading.py:864:run
/Users/monstar/Envs/Spider/lib/python3.6/site-packages/twisted/_threads/_threadworker.py:46:work
/Users/monstar/Envs/Spider/lib/python3.6/site-packages/twisted/_threads/_team.py:190:doWork
--- <exception caught here> ---
/Users/monstar/Envs/Spider/lib/python3.6/site-packages/twisted/python/threadpool.py:250:inContext
/Users/monstar/Envs/Spider/lib/python3.6/site-packages/twisted/python/threadpool.py:266:<lambda>
/Users/monstar/Envs/Spider/lib/python3.6/site-packages/twisted/python/context.py:122:callWithContext
/Users/monstar/Envs/Spider/lib/python3.6/site-packages/twisted/python/context.py:85:callWithContext
/Users/monstar/Envs/Spider/lib/python3.6/site-packages/twisted/enterprise/adbapi.py:477:_runInteraction
/Users/monstar/Envs/Spider/lib/python3.6/site-packages/twisted/python/compat.py:477:reraise
/Users/monstar/Envs/Spider/lib/python3.6/site-packages/twisted/enterprise/adbapi.py:467:_runInteraction
/Users/monstar/Desktop/ProjectCode/bigdatarecruit/SpiderMan/RecruitSpider/RecruitSpider/pipelines.py:104:do_insert_company
/Users/monstar/Desktop/ProjectCode/bigdatarecruit/SpiderMan/RecruitSpider/RecruitSpider/items.py:254:get_zhilian_company_insert_sql
/Users/monstar/Envs/Spider/lib/python3.6/site-packages/scrapy/item.py:59:__getitem__
]